<mujoco model="MuJoCo Model">
  <compiler angle="radian"/>

  <worldbody>
    <body name="torso" pos="0 0 0.5">
      <site name="torso_site" pos="0 0 0.05" type="sphere" rgba="1 0 0 1"/>            
      <joint name="torso_joint" type="free" limited="false" actuatorfrclimited="false"/>
      <geom size="0.165 0.08255 0.0762" type="box" mass="11.25" rgba="0.694118 0.65098 0.533333 1"/>
      
      <body name="torso_left_thigh" pos="-0.0761 0.10795 0">
        <joint name="torso_left_thigh_joint" pos="0 0 0" axis="0 1 0" armature="0.0072" damping="5"/>
        <geom name="torso_left_thigh_geom" size="0.02 0.0508" pos="0 0.02 -0.0508" type="capsule" mass="0.5" rgba="0.694118 0.65098 0.533333 1"/>
        <site name="tl_thigh_site" pos="0 0 0" rgba="1 0 0 1"/>            
        
        <body name="torso_left_shin" pos="0 0.06135 -0.1016">
          <joint name="torso_left_thigh_shin_joint" pos="0 0 0" axis="0 1 0" armature="0.01805" damping="5"/>
          <geom name="torso_left_shin_geom" size="0.015 0.08255" quat="0.707107 0 0.707107 0" type="capsule" mass="0.5" rgba="0.694118 0.65098 0.533333 1"/>
          <site name="tl_shin_site" pos="0 0 0" rgba="1 0 0 1"/>            
          
          <body name="torso_left_front_wheel" pos="0.08255 0.04675 0">
            <geom name="torso_left_front_wheel_geom" size="0.0635 0.0635 0.03175" quat="0.707107 0.707107 0 0" type="ellipsoid" solref="0.2 0.5" mass="0.5" rgba="0.694118 0.65098 0.533333 1"/>
            <site name="tlf_wheel_site" pos="0 0 0" size="0.0635 0.0635 0.03175" quat="0.707107 0.707107 0 0" type="ellipsoid" rgba="1 0 0 1"/>            
          </body>
          
          <body name="torso_left_rear_wheel" pos="-0.08255 0.04675 0">
            <geom name="torso_left_rear_wheel_geom" size="0.0635 0.0635 0.03175" quat="0.707107 0.707107 0 0" type="ellipsoid" solref="0.2 0.5" mass="0.5" rgba="0.694118 0.65098 0.533333 1"/>
            <site name="tlr_wheel_site" pos="0 0 0" size="0.0635 0.0635 0.03175" quat="0.707107 0.707107 0 0" type="ellipsoid" rgba="1 0 0 1"/>            
          </body>
        </body>
      </body>
      
      <body name="torso_right_thigh" pos="-0.0761 -0.10795 0">
        <joint name="torso_right_thigh_joint" pos="0 0 0" axis="0 1 0" armature="0.0072" damping="5"/>
        <geom name="torso_right_thigh_geom" size="0.02 0.0508" pos="0 -0.02 -0.0508" type="capsule" mass="0.5" rgba="0.694118 0.65098 0.533333 1"/>
        <site name="tr_thigh_site" pos="0 0 0" rgba="1 0 0 1"/>            
        
        <body name="torso_right_shin" pos="0 -0.06135 -0.1016">
          <joint name="torso_right_thigh_shin_joint" pos="0 0 0" axis="0 1 0" armature="0.01805" damping="5"/>
          <geom name="torso_right_shin_geom" size="0.015 0.08255" quat="0.707107 0 0.707107 0" type="capsule" mass="0.5" rgba="0.694118 0.65098 0.533333 1"/>
          <site name="tr_shin_site" pos="0 0 0" rgba="1 0 0 1"/>            
          
          <body name="torso_right_front_wheel" pos="0.08255 -0.04675 0">
            <geom name="torso_right_front_wheel_geom" size="0.0635 0.0635 0.03175" quat="0.707107 0.707107 0 0" type="ellipsoid" solref="0.2 0.5" mass="0.5" rgba="0.694118 0.65098 0.533333 1"/>
            <site name="trf_wheel_site" pos="0 0 0" size="0.0635 0.0635 0.03175" quat="0.707107 0.707107 0 0" type="ellipsoid" rgba="1 0 0 1"/>            
          </body>
          
          <body name="torso_right_rear_wheel" pos="-0.08255 -0.04675 0">
            <geom name="torso_right_rear_wheel_geom" size="0.0635 0.0635 0.03175" quat="0.707107 0.707107 0 0" type="ellipsoid" solref="0.2 0.5" mass="0.5" rgba="0.694118 0.65098 0.533333 1"/>
            <site name="trr_wheel_site" pos="0 0 0" size="0.0635 0.0635 0.03175" quat="0.707107 0.707107 0 0" type="ellipsoid" rgba="1 0 0 1"/>            
          </body>
        </body>
      </body>
      
      <body name="head" pos="0.376 0 0">
        <geom size="0.165 0.08255 0.0762" type="box" mass="11.25" rgba="0.694118 0.65098 0.533333 1"/>
        
        <body name="head_left_thigh" pos="0.0761 0.10795 0">
          <joint name="head_left_thigh_joint" pos="0 0 0" axis="0 1 0" armature="0.0072" damping="5"/>
          <geom name="head_left_thigh_geom" size="0.02 0.0508" pos="0 0.02 -0.0508" type="capsule" mass="0.5" rgba="0.694118 0.65098 0.533333 1"/>
          <site name="hl_thigh_site" pos="0 0 0" rgba="1 0 0 1"/>            
          
          <body name="head_left_shin" pos="0 0.06135 -0.1016">
            <joint name="head_left_thigh_shin_joint" pos="0 0 0" axis="0 1 0" armature="0.01805" damping="5"/>
            <geom name="head_left_shin_geom" size="0.015 0.08255" quat="0.707107 0 0.707107 0" type="capsule" mass="0.5" rgba="0.694118 0.65098 0.533333 1"/>
            <site name="hl_shin_site" pos="0 0 0" rgba="1 0 0 1"/>            
            
            <body name="head_left_front_wheel" pos="0.08255 0.04675 0">
              <geom name="head_left_front_wheel_geom" size="0.0635 0.0635 0.03175" quat="0.707107 0.707107 0 0" type="ellipsoid" solref="0.2 0.5" mass="0.5" rgba="0.694118 0.65098 0.533333 1"/>
              <site name="hlf_wheel_site" pos="0 0 0" size="0.0635 0.0635 0.03175" quat="0.707107 0.707107 0 0" type="ellipsoid" rgba="1 0 0 1"/>            
            </body>
            
            <body name="head_left_rear_wheel" pos="-0.08255 0.04675 0">
              <geom name="head_left_rear_wheel_geom" size="0.0635 0.0635 0.03175" quat="0.707107 0.707107 0 0" type="ellipsoid" solref="0.2 0.5" mass="0.5" rgba="0.694118 0.65098 0.533333 1"/>
              <site name="hlr_wheel_site" pos="0 0 0" size="0.0635 0.0635 0.03175" quat="0.707107 0.707107 0 0" type="ellipsoid" rgba="1 0 0 1"/>            
              </body>
          </body>
        </body>
        
        <body name="head_right_thigh" pos="0.0761 -0.10795 0">
          <joint name="head_right_thigh_joint" pos="0 0 0" axis="0 1 0" armature="0.0072" damping="5"/>
          <geom name="head_right_thigh_geom" size="0.02 0.0508" pos="0 -0.02 -0.0508" type="capsule" mass="0.5" rgba="0.694118 0.65098 0.533333 1"/>
          <site name="hr_thigh_site" pos="0 0 0" rgba="1 0 0 1"/>            
          
          <body name="head_right_shin" pos="0 -0.06135 -0.1016">
            <joint name="head_right_thigh_shin_joint" pos="0 0 0" axis="0 1 0" armature="0.01805" damping="5"/>
            <geom name="head_right_shin_geom" size="0.015 0.08255" quat="0.707107 0 0.707107 0" type="capsule" mass="0.5" rgba="0.694118 0.65098 0.533333 1"/>
            <site name="hr_shin_site" pos="0 0 0" rgba="1 0 0 1"/>

            <body name="head_right_front_wheel" pos="0.08255 -0.04675 0">
              <geom name="head_right_front_wheel_geom" size="0.0635 0.0635 0.03175" quat="0.707107 0.707107 0 0" type="ellipsoid" solref="0.2 0.5" mass="0.5" rgba="0.694118 0.65098 0.533333 1"/>
              <site name="hrf_wheel_site" pos="0 0 0" size="0.0635 0.0635 0.03175" quat="0.707107 0.707107 0 0" type="ellipsoid" rgba="1 0 0 1"/>            
            </body>

            <body name="head_right_rear_wheel" pos="-0.08255 -0.04675 0">
              <geom name="head_right_rear_wheel_geom" size="0.0635 0.0635 0.03175" quat="0.707107 0.707107 0 0" type="ellipsoid" solref="0.2 0.5" mass="0.5" rgba="0.694118 0.65098 0.533333 1"/>
              <site name="hrr_wheel_site" pos="0 0 0" size="0.0635 0.0635 0.03175" quat="0.707107 0.707107 0 0" type="ellipsoid" rgba="1 0 0 1"/>            
              <site name="hrr_xaxis" type="capsule" size="0.005 0.04" pos="0.04 0 0" quat="0.707107 0 0.707107 0" rgba="1 0 0 1"/>
              <site name="hrr_yaxis" type="capsule" size="0.005 0.04" pos="0 -0.04 0" quat="0.707107 -0.707107 0 0" rgba="0 1 0 1"/>
              <site name="hrr_zaxis" type="capsule" size="0.005 0.04" pos="0 0 0.04" quat="1 0 0 0" rgba="0 0 1 1"/>              
            </body>
          </body>
        </body>
      </body>
    </body>
  </worldbody>

  <actuator>
    <general name="bl_hip" joint="torso_left_thigh_joint"/>
    <general name="bl_knee" joint="torso_left_thigh_shin_joint"/>
    <!-- <general name="bl_wheel1_joint" joint="torso_left_shin_front_wheel_joint"/> -->
    <!-- <general name="bl_wheel2_joint" joint="torso_left_shin_rear_wheel_joint"/> -->
    <general name="br_hip" joint="torso_right_thigh_joint"/>
    <general name="br_knee" joint="torso_right_thigh_shin_joint"/>
    <!-- <general name="br_wheel1_joint" joint="torso_right_shin_front_wheel_joint"/> -->
    <!-- <general name="br_wheel2_joint" joint="torso_right_shin_rear_wheel_joint"/> -->
    <general name="fl_hip" joint="head_left_thigh_joint"/>
    <general name="fl_knee" joint="head_left_thigh_shin_joint"/>
    <!-- <general name="fl_wheel1_joint" joint="head_left_shin_front_wheel_joint"/> -->
    <!-- <general name="fl_wheel2_joint" joint="head_left_shin_rear_wheel_joint"/> -->
    <general name="fr_hip" joint="head_right_thigh_joint"/>
    <general name="fr_knee" joint="head_right_thigh_shin_joint"/>
    <!-- <general name="fr_wheel1_joint" joint="head_right_shin_front_wheel_joint"/> -->
    <!-- <general name="fr_wheel2_joint" joint="head_right_shin_rear_wheel_joint"/> -->
  </actuator>

    <!-- key frame has 0,0 for wheel sites because the bodies have the positions fixed/initialized (k0 - z -) -->
    <keyframe>
      <key name="home"       
        qpos="0 0 0.1675 1 0 0 0 
              0 0 
              0 0 
              0 0 
              0 0"
        ctrl="0 0 
              0 0 
              0 0 
              0 0"/>
      <key name="flat"       
        qpos='0 0 0.05 1 0 0 0 1.71253 -1.71287 1.71253 -1.71287 -1.71253 1.71287 -1.71253 1.71287'
        ctrl="0 0 
              0 0 
              0 0 
              0 0"/>
      <key name="flat_up"       
        qpos='0.0898423 -0.0025112 0.05 1 0 0 0 3.14 3.14 3.14 3.14 3.14 3.14 3.14 3.14'
        ctrl="0 0 
              0 0 
              0 0 
              0 0"/>
      <key name="fortumbling"       
        qpos="0 0 0.13 1 0 0 0 
              1.5708 0 
              1.5708 0
              -1.5708 0
              -1.5708 0"
        ctrl="0 0 
              0 0 
              0 0 
              0 0"/>
      <key name="fortumbling2"       
        qpos="0 0 0.13 1 0 0 0 
              0.659736 -0.659736 
              0.659736 -0.659736
              -0.659736 0.659736
              -0.659736 0.659736"
        ctrl="0 0 
              0 0 
              0 0 
              0 0"/>
      <key name="shinup30deg"       
        qpos="0 0 0.19 1 0 0 0 
              0.534 0 
              0.534 0
              -0.534 0
              -0.534 0"
        ctrl="0 0 
              0 0 
              0 0 
              0 0"/>                                                
    </keyframe>
        <!-- qpos='0.0898423 -0.0025112 0.05 1 0 0 0 3.62333 -5.46591 3.62333 -5.46591 3.62333 -5.46591 3.62333 -5.46591 ' -->
</mujoco>